[2023-06-14T14:05:46.187+0000] {taskinstance.py:1083} INFO - Dependencies all met for <TaskInstance: database_postgres.insert_into_table manual__2023-06-14T14:05:43.496008+00:00 [queued]>
[2023-06-14T14:05:46.192+0000] {taskinstance.py:1083} INFO - Dependencies all met for <TaskInstance: database_postgres.insert_into_table manual__2023-06-14T14:05:43.496008+00:00 [queued]>
[2023-06-14T14:05:46.193+0000] {taskinstance.py:1279} INFO - 
--------------------------------------------------------------------------------
[2023-06-14T14:05:46.193+0000] {taskinstance.py:1280} INFO - Starting attempt 1 of 1
[2023-06-14T14:05:46.194+0000] {taskinstance.py:1281} INFO - 
--------------------------------------------------------------------------------
[2023-06-14T14:05:46.202+0000] {taskinstance.py:1300} INFO - Executing <Task(PostgresOperator): insert_into_table> on 2023-06-14 14:05:43.496008+00:00
[2023-06-14T14:05:46.206+0000] {standard_task_runner.py:55} INFO - Started process 80 to run task
[2023-06-14T14:05:46.209+0000] {standard_task_runner.py:82} INFO - Running: ['***', 'tasks', 'run', 'database_postgres', 'insert_into_table', 'manual__2023-06-14T14:05:43.496008+00:00', '--job-id', '41', '--raw', '--subdir', 'DAGS_FOLDER/postgress_db.py', '--cfg-path', '/tmp/tmp9ny_lh83']
[2023-06-14T14:05:46.210+0000] {standard_task_runner.py:83} INFO - Job 41: Subtask insert_into_table
[2023-06-14T14:05:46.260+0000] {task_command.py:388} INFO - Running <TaskInstance: database_postgres.insert_into_table manual__2023-06-14T14:05:43.496008+00:00 [running]> on host 5fd7c6d884b5
[2023-06-14T14:05:46.307+0000] {taskinstance.py:1509} INFO - Exporting the following env vars:
AIRFLOW_CTX_DAG_OWNER=***
AIRFLOW_CTX_DAG_ID=database_postgres
AIRFLOW_CTX_TASK_ID=insert_into_table
AIRFLOW_CTX_EXECUTION_DATE=2023-06-14T14:05:43.496008+00:00
AIRFLOW_CTX_TRY_NUMBER=1
AIRFLOW_CTX_DAG_RUN_ID=manual__2023-06-14T14:05:43.496008+00:00
[2023-06-14T14:05:46.309+0000] {sql.py:254} INFO - Executing: INSERT INTO my_table (execution_time) VALUES (CURRENT_TIMESTAMP);
[2023-06-14T14:05:46.316+0000] {base.py:73} INFO - Using connection ID 'postgres' for task execution.
[2023-06-14T14:05:46.413+0000] {base.py:73} INFO - Using connection ID 'postgres' for task execution.
[2023-06-14T14:05:46.418+0000] {sql.py:375} INFO - Running statement: INSERT INTO my_table (execution_time) VALUES (CURRENT_TIMESTAMP);, parameters: None
[2023-06-14T14:05:46.420+0000] {taskinstance.py:1768} ERROR - Task failed with exception
Traceback (most recent call last):
  File "/home/airflow/.local/lib/python3.7/site-packages/airflow/providers/common/sql/operators/sql.py", line 266, in execute
    **extra_kwargs,
  File "/home/airflow/.local/lib/python3.7/site-packages/airflow/providers/common/sql/hooks/sql.py", line 349, in run
    self._run_command(cur, sql_statement, parameters)
  File "/home/airflow/.local/lib/python3.7/site-packages/airflow/providers/common/sql/hooks/sql.py", line 380, in _run_command
    cur.execute(sql_statement)
psycopg2.errors.UndefinedColumn: column "execution_time" of relation "my_table" does not exist
LINE 1: INSERT INTO my_table (execution_time) VALUES (CURRENT_TIMEST...
                              ^

[2023-06-14T14:05:46.428+0000] {taskinstance.py:1323} INFO - Marking task as FAILED. dag_id=database_postgres, task_id=insert_into_table, execution_date=20230614T140543, start_date=20230614T140546, end_date=20230614T140546
[2023-06-14T14:05:46.436+0000] {standard_task_runner.py:105} ERROR - Failed to execute job 41 for task insert_into_table (column "execution_time" of relation "my_table" does not exist
LINE 1: INSERT INTO my_table (execution_time) VALUES (CURRENT_TIMEST...
                              ^
; 80)
[2023-06-14T14:05:46.462+0000] {local_task_job.py:208} INFO - Task exited with return code 1
[2023-06-14T14:05:46.475+0000] {taskinstance.py:2578} INFO - 0 downstream tasks scheduled from follow-on schedule check
